Workbook

Sheet CONTROLE
A1: Template de mapa da placa — preencher e duplicar para cada nova placa
A2: Planilha de controle de placas e lanes checada? | B2: Não | F2: Protocolo
A3: Número da placa | B3: 18 | F3: 1. Antes de começar, defina o número da placa de acordo com a planilha Controle de Placas e Lanes_CMMZ.xlsx. Preencha a planilha com todas as informações.
A4: Responsável (Docente/Discente) | F4: 2. Imprima o CheckList de bancada e cole no caderno de laboratório, na página correspondente ao início da preparação das bibliotecas.
A5: Kit de preparação de Bibliotecas | B5: NEBNext UDI Set 1 (E6440) | F5: 3. Preencha todos os campos ao lado, indicando qual o kit de bibliotecas utilizado.
A6: Data de início das bibliotecas | F6: 4. Caso o kit utilizado se o Kapa HyperPrep, escolha os índices iTru na aba "Indices_iTru"desta planilha, e preecha as colunas M e O na Aba 1.Bibliotecas com os nomes dos índices apenas, tomando cuidado para não usar a mesma combinação de índices em mais de uma amostra. As colunas T, U, V e W serão preenchidas automaticamente, e esses dados deverão ser informados ao centro de sequenciamento no momento do envio.
A7: Status da preparação das bibliotecas | F7: 5. Caso o kit utilizado seja QIAseq ou NEBNext, confira qual kit está sendo usado, e copie os nomes dos índices correspondentes a partir das abas Indices_QIAseq ou Indices_NEBNext nesta planilha.
A8: Nome para Caixa de bibliotecas | B8: =concatenate("CMMZ-Placa",$B$3,"-Bibliotecas") -> CMMZ-Placa18-Bibliotecas | F8: 6. Adicione às colunas Espécie, Código de Extração e Concentração de DNA extração as informações de forma idêntica ao informado na planilha de extração do laboratório de origem.
A9: Data de termino das bibliotecas | F9: 7. Na coluna G (DNA Total da Extração) substitua o número 100 pelo volume de elução da sua extração.
A10: Pool de Enriquecimento | B10: Não | F10: 8. Preencha as colunas Data e Técnico apenas na data da execução das bibliotecas.
A11: Kit de Enriquecimento | F11: 9. Decida os tempos e volumes de sonicação, se necessário. O modelo da planilha contem as fórmulas para cálculo automático, com o valor base de 100 ng total. Caso deseje usar uma quantidade diferente de DNA, substitua o número 100 pelo número desejado nas fórmulas das colunas H e I.
A12: Número de Pools de Enriquecimento | F12: 10. Durante a preparação das bibliotecas, pode-se usar os números simples da coluna A para marcação dos tubos.
A13: Número de amostras por Pool de Enriquecimento | F13: 11. Para armazenamento das bibliotecas, deve-se usar nos tubos os nomes de acordo com o listado nas colunas R (para a tamba do tubo) e S (para a lateral do tudo). Não esquecer de adicionar a informação Pre-PCR ou Pós-PCR, de acordo com o conteúdo dos tubos.
A14: Data de início do Enriquecimento | F14: 12. Armazenar as bibliotecas em caixas próprias para tubos, identificando a caixa com o nome de acordo com a linha 7 - Caixa bibliotecas.
A15: Status da preparação do Enriquecimento | F15: 13. Caso prossiga para enriquecimento das amostras, marcar sim no menu da linha 8. Caso não vá fazer enriquecimento, marcar como não.
A16: Nome para Caixa de Enriquecimento e Sequenciamento | B16: =concatenate("CMMZ-Placa",$B$3,"-Sequenciamento") -> CMMZ-Placa18-Sequenciamento | F16: 14. Inclua em tempo real as datas de início e fim da preparação de cada etapa.
A17: Pool de Sequenciamento | B17: Sim | F17: 15. Caso seja feito gel para as biblotecas, colar as imagens na aba 1. Bibliotecas, abaixo da tabela principal
A18: Data de preparação da Pool de Sequenciamento | B18: 46097
A19: Número de amostras na Pool de Sequenciamento
A20: Sequenciamento de mais de uma placa por lane?
A21: Se sim, qual placa foi combinada?
A22: Nome da Lane de Sequenciamento
A23: Data de envio para Sequenciamento
A24: Data de recebimento dos dados
A25: Planilha de controle de placas e lanes atualizada?

Sheet 1.Bibliotecas
B1: PREENCHER DIARIAMENTE | D1: PREENCHER CONFORME PLANILHA DE EXTRAÇAO | G1: DEFINIR QUANTIDADE DE DNA PARA SONICAR, DILUIÇAO E TEMPO DE SONICAÇAO | L1: DEFINIR INDICES UNICOS
A2: Nº Amostra | B2: Data | C2: Técnico | D2: Espécie | E2: Código extração | F2: DNA extração (ng/µL) | G2: DNA Total na extração (ng) | H2: Volume de DNA (uL) para shearing | I2: Volume de água H2O (uL) para shearing | J2: Shear Time (s) | K2: Input total de DNA (ng) na biblioteca | L2: Posição i7 | M2: Índice i7 | N2: Posição i5 | O2: Índice i5 | P2: Post-PCR 13x (ng/uL) | Q2: ID Biblioteca | R2: Tubo tampa | S2: Tubo lateral | T2: i7Index name | U2: Index-seq_1 | V2: i5 Index name | W2: Index-seq | X2: FASTQ R1 | Y2: FASTQ R2
A3: 1 | B3: 46097 | D3: Teste | E3: Teste | G3: =100*F3 -> 0 | H3: =IF(G3<=100,100,100/F3) -> 100 | I3: =100-H3 -> 0 | K3: =H3*F3 -> 0 | L3: A01 | M3: iTru7_107_04 | N3: A01 | O3: iTru5_117_A | Q3: =IF(ISBLANK(CONTROLE!$B$3),"","CMMZ_P"&CONTROLE!$B$3&"_0"&A3) -> CMMZ_P18_01 | R3: =IF(ISBLANK(CONTROLE!$B$3),"","P"&CONTROLE!$B$3&"_0"&A3) -> P18_01 | S3: ="CMMZ_P"&CONTROLE!$B$3&"_"&TEXT(A4,"00")&"_"&TEXT(B3,"ddMMMyy") -> CMMZ_P18_02_16Mar26 | T3: {=IFERROR(VLOOKUP(M3,{Indices_iTru!B:C;Indices_NEBNext!C:D;Indices_QIAseq!B:C},1,FALSE),"")} -> iTru7_107_04 | U3: {=IFERROR(VLOOKUP(M3,{Indices_iTru!B:C;Indices_NEBNext!C:D;Indices_QIAseq!B:C},2,FALSE),"")} -> GTCGAAGA | V3: {=IFERROR(VLOOKUP(O3,{Indices_iTru!B:C;Indices_NEBNext!E:F;Indices_QIAseq!D:E},1,FALSE),"")} -> iTru5_117_A | W3: {=IFERROR(VLOOKUP(O3,{Indices_iTru!B:C;Indices_NEBNext!E:F;Indices_QIAseq!D:E},2,FALSE),"")} -> CAGAGTGA | X3: =CONCATENATE(D3,"_",E3,"_",U3,"+",W3,"_R1.fastq.gz") -> Teste_Teste_GTCGAAGA+CAGAGTGA_R1.fastq.gz | Y3: =CONCATENATE(D3,"_",E3,"_",U3,"+",W3,"_R2.fastq.gz") -> Teste_Teste_GTCGAAGA+CAGAGTGA_R2.fastq.gz
A4: 2 | G4: =100*F4 -> 0 | H4: =IF(G4<=100,100,100/F4) -> 100 | I4: =100-H4 -> 0 | K4: =H4*F4 -> 0 | L4: A02 | M4: S762 | N4: A02 | O4: S512 | Q4: =IF(ISBLANK(CONTROLE!$B$3),"","CMMZ_P"&CONTROLE!$B$3&"_0"&A4) -> CMMZ_P18_02 | R4: =IF(ISBLANK(CONTROLE!$B$3),"","P"&CONTROLE!$B$3&"_0"&A4) -> P18_02 | S4: ="CMMZ_P"&CONTROLE!$B$3&"_"&TEXT(A5,"00")&"_"&TEXT(B4,"ddMMMyy") -> CMMZ_P18_03_30Dec99 | T4: {=IFERROR(VLOOKUP(M4,{Indices_iTru!B:C;Indices_NEBNext!C:D;Indices_QIAseq!B:C},1,FALSE),"")} -> S762 | U4: {=IFERROR(VLOOKUP(M4,{Indices_iTru!B:C;Indices_NEBNext!C:D;Indices_QIAseq!B:C},2,FALSE),"")} -> TTACCGAC | V4: {=IFERROR(VLOOKUP(O4,{Indices_iTru!B:C;Indices_NEBNext!E:F;Indices_QIAseq!D:E},1,FALSE),"")} -> S512 | W4: {=IFERROR(VLOOKUP(O4,{Indices_iTru!B:C;Indices_NEBNext!E:F;Indices_QIAseq!D:E},2,FALSE),"")} -> CGTATTCG | X4: =CONCATENATE(D4,"_",E4,"_",U4,"+",W4,"_R1.fastq.gz") -> __TTACCGAC+CGTATTCG_R1.fastq.gz | Y4: =CONCATENATE(D4,"_",E4,"_",U4,"+",W4,"_R2.fastq.gz") -> __TTACCGAC+CGTATTCG_R2.fastq.gz
A5: 3 | G5: =100*F5 -> 0 | H5: =IF(G5<=100,100,100/F5) -> 100 | I5: =100-H5 -> 0 | K5: =H5*F5 -> 0 | L5: A03 | M5: i7QDIY-001 | N5: A03 | O5: i5QDIY-001 | Q5: =IF(ISBLANK(CONTROLE!$B$3),"","CMMZ_P"&CONTROLE!$B$3&"_0"&A5) -> CMMZ_P18_03 | R5: =IF(ISBLANK(CONTROLE!$B$3),"","P"&CONTROLE!$B$3&"_0"&A5) -> P18_03 | S5: ="CMMZ_P"&CONTROLE!$B$3&"_"&TEXT(A6,"00")&"_"&TEXT(B5,"ddMMMyy") -> CMMZ_P18_04_30Dec99 | T5: {=IFERROR(VLOOKUP(M5,{Indices_iTru!B:C;Indices_NEBNext!C:D;Indices_QIAseq!B:C},1,FALSE),"")} -> i7QDIY-001 | U5: {=IFERROR(VLOOKUP(M5,{Indices_iTru!B:C;Indices_NEBNext!C:D;Indices_QIAseq!B:C},2,FALSE),"")} -> TGAACGTTGT | V5: {=IFERROR(VLOOKUP(O5,{Indices_iTru!B:C;Indices_NEBNext!E:F;Indices_QIAseq!D:E},1,FALSE),"")} -> i5QDIY-001 | W5: {=IFERROR(VLOOKUP(O5,{Indices_iTru!B:C;Indices_NEBNext!E:F;Indices_QIAseq!D:E},2,FALSE),"")} -> ATGGCCGACT | X5: =CONCATENATE(D5,"_",E5,"_",U5,"+",W5,"_R1.fastq.gz") -> __TGAACGTTGT+ATGGCCGACT_R1.fastq.gz | Y5: =CONCATENATE(D5,"_",E5,"_",U5,"+",W5,"_R2.fastq.gz") -> __TGAACGTTGT+ATGGCCGACT_R2.fastq.gz
A6: 4 | G6: =100*F6 -> 0 | H6: =IF(G6<=100,100,100/F6) -> 100 | I6: =100-H6 -> 0 | K6: =H6*F6 -> 0 | L6: A04 | N6: A04 | Q6: =IF(ISBLANK(CONTROLE!$B$3),"","CMMZ_P"&CONTROLE!$B$3&"_0"&A6) -> CMMZ_P18_04 | R6: =IF(ISBLANK(CONTROLE!$B$3),"","P"&CONTROLE!$B$3&"_0"&A6) -> P18_04 | S6: ="CMMZ_P"&CONTROLE!$B$3&"_"&TEXT(A7,"00")&"_"&TEXT(B6,"ddMMMyy") -> CMMZ_P18_05_30Dec99 | T6: {=IFERROR(VLOOKUP(M6,{Indices_iTru!B:C;Indices_NEBNext!C:D;Indices_QIAseq!B:C},1,FALSE),"")} | U6: {=IFERROR(VLOOKUP(M6,{Indices_iTru!B:C;Indices_NEBNext!C:D;Indices_QIAseq!B:C},2,FALSE),"")} | V6: {=IFERROR(VLOOKUP(O6,{Indices_iTru!B:C;Indices_NEBNext!E:F;Indices_QIAseq!D:E},1,FALSE),"")} | W6: {=IFERROR(VLOOKUP(O6,{Indices_iTru!B:C;Indices_NEBNext!E:F;Indices_QIAseq!D:E},2,FALSE),"")} | X6: =CONCATENATE(D6,"_",E6,"_",U6,"+",W6,"_R1.fastq.gz") -> __+_R1.fastq.gz | Y6: =CONCATENATE(D6,"_",E6,"_",U6,"+",W6,"_R2.fastq.gz") -> __+_R2.fastq.gz
A7: 5 | G7: =100*F7 -> 0 | H7: =IF(G7<=100,100,100/F7) -> 100 | I7: =100-H7 -> 0 | K7: =H7*F7 -> 0 | L7: A05 | N7: A05 | Q7: =IF(ISBLANK(CONTROLE!$B$3),"","CMMZ_P"&CONTROLE!$B$3&"_0"&A7) -> CMMZ_P18_05 | R7: =IF(ISBLANK(CONTROLE!$B$3),"","P"&CONTROLE!$B$3&"_0"&A7) -> P18_05 | S7: ="CMMZ_P"&CONTROLE!$B$3&"_"&TEXT(A8,"00")&"_"&TEXT(B7,"ddMMMyy") -> CMMZ_P18_06_30Dec99 | T7: {=IFERROR(VLOOKUP(M7,{Indices_iTru!B:C;Indices_NEBNext!C:D;Indices_QIAseq!B:C},1,FALSE),"")} | U7: {=IFERROR(VLOOKUP(M7,{Indices_iTru!B:C;Indices_NEBNext!C:D;Indices_QIAseq!B:C},2,FALSE),"")} | V7: {=IFERROR(VLOOKUP(O7,{Indices_iTru!B:C;Indices_NEBNext!E:F;Indices_QIAseq!D:E},1,FALSE),"")} | W7: {=IFERROR(VLOOKUP(O7,{Indices_iTru!B:C;Indices_NEBNext!E:F;Indices_QIAseq!D:E},2,FALSE),"")} | X7: =CONCATENATE(D7,"_",E7,"_",U7,"+",W7,"_R1.fastq.gz") -> __+_R1.fastq.gz | Y7: =CONCATENATE(D7,"_",E7,"_",U7,"+",W7,"_R2.fastq.gz") -> __+_R2.fastq.gz
A8: 6 | G8: =100*F8 -> 0 | H8: =IF(G8<=100,100,100/F8) -> 100 | I8: =100-H8 -> 0 | K8: =H8*F8 -> 0 | L8: A06 | N8: A06 | Q8: =IF(ISBLANK(CONTROLE!$B$3),"","CMMZ_P"&CONTROLE!$B$3&"_0"&A8) -> CMMZ_P18_06 | R8: =IF(ISBLANK(CONTROLE!$B$3),"","P"&CONTROLE!$B$3&"_0"&A8) -> P18_06 | S8: ="CMMZ_P"&CONTROLE!$B$3&"_"&TEXT(A9,"00")&"_"&TEXT(B8,"ddMMMyy") -> CMMZ_P18_07_30Dec99 | T8: {=IFERROR(VLOOKUP(M8,{Indices_iTru!B:C;Indices_NEBNext!C:D;Indices_QIAseq!B:C},1,FALSE),"")} | U8: {=IFERROR(VLOOKUP(M8,{Indices_iTru!B:C;Indices_NEBNext!C:D;Indices_QIAseq!B:C},2,FALSE),"")} | V8: {=IFERROR(VLOOKUP(O8,{Indices_iTru!B:C;Indices_NEBNext!E:F;Indices_QIAseq!D:E},1,FALSE),"")} | W8: {=IFERROR(VLOOKUP(O8,{Indices_iTru!B:C;Indices_NEBNext!E:F;Indices_QIAseq!D:E},2,FALSE),"")} | X8: =CONCATENATE(D8,"_",E8,"_",U8,"+",W8,"_R1.fastq.gz") -> __+_R1.fastq.gz | Y8: =CONCATENATE(D8,"_",E8,"_",U8,"+",W8,"_R2.fastq.gz") -> __+_R2.fastq.gz
A9: 7 | G9: =100*F9 -> 0 | H9: =IF(G9<=100,100,100/F9) -> 100 | I9: =100-H9 -> 0 | K9: =H9*F9 -> 0 | L9: A07 | N9: A07 | Q9: =IF(ISBLANK(CONTROLE!$B$3),"","CMMZ_P"&CONTROLE!$B$3&"_0"&A9) -> CMMZ_P18_07 | R9: =IF(ISBLANK(CONTROLE!$B$3),"","P"&CONTROLE!$B$3&"_0"&A9) -> P18_07 | S9: ="CMMZ_P"&CONTROLE!$B$3&"_"&TEXT(A10,"00")&"_"&TEXT(B9,"ddMMMyy") -> CMMZ_P18_08_30Dec99 | T9: {=IFERROR(VLOOKUP(M9,{Indices_iTru!B:C;Indices_NEBNext!C:D;Indices_QIAseq!B:C},1,FALSE),"")} | U9: {=IFERROR(VLOOKUP(M9,{Indices_iTru!B:C;Indices_NEBNext!C:D;Indices_QIAseq!B:C},2,FALSE),"")} | V9: {=IFERROR(VLOOKUP(O9,{Indices_iTru!B:C;Indices_NEBNext!E:F;Indices_QIAseq!D:E},1,FALSE),"")} | W9: {=IFERROR(VLOOKUP(O9,{Indices_iTru!B:C;Indices_NEBNext!E:F;Indices_QIAseq!D:E},2,FALSE),"")} | X9: =CONCATENATE(D9,"_",E9,"_",U9,"+",W9,"_R1.fastq.gz") -> __+_R1.fastq.gz | Y9: =CONCATENATE(D9,"_",E9,"_",U9,"+",W9,"_R2.fastq.gz") -> __+_R2.fastq.gz
A10: 8 | G10: =100*F10 -> 0 | H10: =IF(G10<=100,100,100/F10) -> 100 | I10: =100-H10 -> 0 | K10: =H10*F10 -> 0 | L10: A08 | N10: A08 | Q10: =IF(ISBLANK(CONTROLE!$B$3),"","CMMZ_P"&CONTROLE!$B$3&"_0"&A10) -> CMMZ_P18_08 | R10: =IF(ISBLANK(CONTROLE!$B$3),"","P"&CONTROLE!$B$3&"_0"&A10) -> P18_08 | S10: ="CMMZ_P"&CONTROLE!$B$3&"_"&TEXT(A11,"00")&"_"&TEXT(B10,"ddMMMyy") -> CMMZ_P18_09_30Dec99 | T10: {=IFERROR(VLOOKUP(M10,{Indices_iTru!B:C;Indices_NEBNext!C:D;Indices_QIAseq!B:C},1,FALSE),"")} | U10: {=IFERROR(VLOOKUP(M10,{Indices_iTru!B:C;Indices_NEBNext!C:D;Indices_QIAseq!B:C},2,FALSE),"")} | V10: {=IFERROR(VLOOKUP(O10,{Indices_iTru!B:C;Indices_NEBNext!E:F;Indices_QIAseq!D:E},1,FALSE),"")} | W10: {=IFERROR(VLOOKUP(O10,{Indices_iTru!B:C;Indices_NEBNext!E:F;Indices_QIAseq!D:E},2,FALSE),"")} | X10: =CONCATENATE(D10,"_",E10,"_",U10,"+",W10,"_R1.fastq.gz") -> __+_R1.fastq.gz | Y10: =CONCATENATE(D10,"_",E10,"_",U10,"+",W10,"_R2.fastq.gz") -> __+_R2.fastq.gz
A11: 9 | G11: =100*F11 -> 0 | H11: =IF(G11<=100,100,100/F11) -> 100 | I11: =100-H11 -> 0 | K11: =H11*F11 -> 0 | L11: A09 | N11: A09 | Q11: =IF(ISBLANK(CONTROLE!$B$3),"","CMMZ_P"&CONTROLE!$B$3&"_0"&A11) -> CMMZ_P18_09 | R11: =IF(ISBLANK(CONTROLE!$B$3),"","P"&CONTROLE!$B$3&"_0"&A11) -> P18_09 | S11: ="CMMZ_P"&CONTROLE!$B$3&"_"&TEXT(A12,"00")&"_"&TEXT(B11,"ddMMMyy") -> CMMZ_P18_10_30Dec99 | T11: {=IFERROR(VLOOKUP(M11,{Indices_iTru!B:C;Indices_NEBNext!C:D;Indices_QIAseq!B:C},1,FALSE),"")} | U11: {=IFERROR(VLOOKUP(M11,{Indices_iTru!B:C;Indices_NEBNext!C:D;Indices_QIAseq!B:C},2,FALSE),"")} | V11: {=IFERROR(VLOOKUP(O11,{Indices_iTru!B:C;Indices_NEBNext!E:F;Indices_QIAseq!D:E},1,FALSE),"")} | W11: {=IFERROR(VLOOKUP(O11,{Indices_iTru!B:C;Indices_NEBNext!E:F;Indices_QIAseq!D:E},2,FALSE),"")} | X11: =CONCATENATE(D11,"_",E11,"_",U11,"+",W11,"_R1.fastq.gz") -> __+_R1.fastq.gz | Y11: =CONCATENATE(D11,"_",E11,"_",U11,"+",W11,"_R2.fastq.gz") -> __+_R2.fastq.gz
A12: 10 | G12: =100*F12 -> 0 | H12: =IF(G12<=100,100,100/F12) -> 100 | I12: =100-H12 -> 0 | K12: =H12*F12 -> 0 | L12: A10 | N12: A10 | Q12: =IF(ISBLANK(CONTROLE!$B$3),"","CMMZ_P"&CONTROLE!$B$3&"_0"&A12) -> CMMZ_P18_010 | R12: =IF(ISBLANK(CONTROLE!$B$3),"","P"&CONTROLE!$B$3&"_0"&A12) -> P18_010 | S12: ="CMMZ_P"&CONTROLE!$B$3&"_"&TEXT(A13,"00")&"_"&TEXT(B12,"ddMMMyy") -> CMMZ_P18_11_30Dec99 | T12: {=IFERROR(VLOOKUP(M12,{Indices_iTru!B:C;Indices_NEBNext!C:D;Indices_QIAseq!B:C},1,FALSE),"")} | U12: {=IFERROR(VLOOKUP(M12,{Indices_iTru!B:C;Indices_NEBNext!C:D;Indices_QIAseq!B:C},2,FALSE),"")} | V12: {=IFERROR(VLOOKUP(O12,{Indices_iTru!B:C;Indices_NEBNext!E:F;Indices_QIAseq!D:E},1,FALSE),"")} | W12: {=IFERROR(VLOOKUP(O12,{Indices_iTru!B:C;Indices_NEBNext!E:F;Indices_QIAseq!D:E},2,FALSE),"")} | X12: =CONCATENATE(D12,"_",E12,"_",U12,"+",W12,"_R1.fastq.gz") -> __+_R1.fastq.gz | Y12: =CONCATENATE(D12,"_",E12,"_",U12,"+",W12,"_R2.fastq.gz") -> __+_R2.fastq.gz
A13: 11 | G13: =100*F13 -> 0 | H13: =IF(G13<=100,100,100/F13) -> 100 | I13: =100-H13 -> 0 | K13: =H13*F13 -> 0 | L13: A11 | N13: A11 | Q13: =IF(ISBLANK(CONTROLE!$B$3),"","CMMZ_P"&CONTROLE!$B$3&"_0"&A13) -> CMMZ_P18_011 | R13: =IF(ISBLANK(CONTROLE!$B$3),"","P"&CONTROLE!$B$3&"_0"&A13) -> P18_011 | S13: ="CMMZ_P"&CONTROLE!$B$3&"_"&TEXT(A14,"00")&"_"&TEXT(B13,"ddMMMyy") -> CMMZ_P18_12_30Dec99 | T13: {=IFERROR(VLOOKUP(M13,{Indices_iTru!B:C;Indices_NEBNext!C:D;Indices_QIAseq!B:C},1,FALSE),"")} | U13: {=IFERROR(VLOOKUP(M13,{Indices_iTru!B:C;Indices_NEBNext!C:D;Indices_QIAseq!B:C},2,FALSE),"")} | V13: {=IFERROR(VLOOKUP(O13,{Indices_iTru!B:C;Indices_NEBNext!E:F;Indices_QIAseq!D:E},1,FALSE),"")} | W13: {=IFERROR(VLOOKUP(O13,{Indices_iTru!B:C;Indices_NEBNext!E:F;Indices_QIAseq!D:E},2,FALSE),"")} | X13: =CONCATENATE(D13,"_",E13,"_",U13,"+",W13,"_R1.fastq.gz") -> __+_R1.fastq.gz | Y13: =CONCATENATE(D13,"_",E13,"_",U13,"+",W13,"_R2.fastq.gz") -> __+_R2.fastq.gz
A14: 12 | G14: =100*F14 -> 0 | H14: =IF(G14<=100,100,100/F14) -> 100 | I14: =100-H14 -> 0 | K14: =H14*F14 -> 0 | L14: A12 | N14: A12 | Q14: =IF(ISBLANK(CONTROLE!$B$3),"","CMMZ_P"&CONTROLE!$B$3&"_0"&A14) -> CMMZ_P18_012 | R14: =IF(ISBLANK(CONTROLE!$B$3),"","P"&CONTROLE!$B$3&"_0"&A14) -> P18_012 | S14: ="CMMZ_P"&CONTROLE!$B$3&"_"&TEXT(A15,"00")&"_"&TEXT(B14,"ddMMMyy") -> CMMZ_P18_13_30Dec99 | T14: {=IFERROR(VLOOKUP(M14,{Indices_iTru!B:C;Indices_NEBNext!C:D;Indices_QIAseq!B:C},1,FALSE),"")} | U14: {=IFERROR(VLOOKUP(M14,{Indices_iTru!B:C;Indices_NEBNext!C:D;Indices_QIAseq!B:C},2,FALSE),"")} | V14: {=IFERROR(VLOOKUP(O14,{Indices_iTru!B:C;Indices_NEBNext!E:F;Indices_QIAseq!D:E},1,FALSE),"")} | W14: {=IFERROR(VLOOKUP(O14,{Indices_iTru!B:C;Indices_NEBNext!E:F;Indices_QIAseq!D:E},2,FALSE),"")} | X14: =CONCATENATE(D14,"_",E14,"_",U14,"+",W14,"_R1.fastq.gz") -> __+_R1.fastq.gz | Y14: =CONCATENATE(D14,"_",E14,"_",U14,"+",W14,"_R2.fastq.gz") -> __+_R2.fastq.gz
A15: 13 | G15: =100*F15 -> 0 | H15: =IF(G15<=100,100,100/F15) -> 100 | I15: =100-H15 -> 0 | K15: =H15*F15 -> 0 | L15: B01 | N15: B01 | Q15: =IF(ISBLANK(CONTROLE!$B$3),"","CMMZ_P"&CONTROLE!$B$3&"_0"&A15) -> CMMZ_P18_013 | R15: =IF(ISBLANK(CONTROLE!$B$3),"","P"&CONTROLE!$B$3&"_0"&A15) -> P18_013 | S15: ="CMMZ_P"&CONTROLE!$B$3&"_"&TEXT(A16,"00")&"_"&TEXT(B15,"ddMMMyy") -> CMMZ_P18_14_30Dec99 | T15: {=IFERROR(VLOOKUP(M15,{Indices_iTru!B:C;Indices_NEBNext!C:D;Indices_QIAseq!B:C},1,FALSE),"")} | U15: {=IFERROR(VLOOKUP(M15,{Indices_iTru!B:C;Indices_NEBNext!C:D;Indices_QIAseq!B:C},2,FALSE),"")} | V15: {=IFERROR(VLOOKUP(O15,{Indices_iTru!B:C;Indices_NEBNext!E:F;Indices_QIAseq!D:E},1,FALSE),"")} | W15: {=IFERROR(VLOOKUP(O15,{Indices_iTru!B:C;Indices_NEBNext!E:F;Indices_QIAseq!D:E},2,FALSE),"")} | X15: =CONCATENATE(D15,"_",E15,"_",U15,"+",W15,"_R1.fastq.gz") -> __+_R1.fastq.gz | Y15: =CONCATENATE(D15,"_",E15,"_",U15,"+",W15,"_R2.fastq.gz") -> __+_R2.fastq.gz
A16: 14 | G16: =100*F16 -> 0 | H16: =IF(G16<=100,100,100/F16) -> 100 | I16: =100-H16 -> 0 | K16: =H16*F16 -> 0 | L16: B02 | N16: B02 | Q16: =IF(ISBLANK(CONTROLE!$B$3),"","CMMZ_P"&CONTROLE!$B$3&"_0"&A16) -> CMMZ_P18_014 | R16: =IF(ISBLANK(CONTROLE!$B$3),"","P"&CONTROLE!$B$3&"_0"&A16) -> P18_014 | S16: ="CMMZ_P"&CONTROLE!$B$3&"_"&TEXT(A17,"00")&"_"&TEXT(B16,"ddMMMyy") -> CMMZ_P18_15_30Dec99 | T16: {=IFERROR(VLOOKUP(M16,{Indices_iTru!B:C;Indices_NEBNext!C:D;Indices_QIAseq!B:C},1,FALSE),"")} | U16: {=IFERROR(VLOOKUP(M16,{Indices_iTru!B:C;Indices_NEBNext!C:D;Indices_QIAseq!B:C},2,FALSE),"")} | V16: {=IFERROR(VLOOKUP(O16,{Indices_iTru!B:C;Indices_NEBNext!E:F;Indices_QIAseq!D:E},1,FALSE),"")} | W16: {=IFERROR(VLOOKUP(O16,{Indices_iTru!B:C;Indices_NEBNext!E:F;Indices_QIAseq!D:E},2,FALSE),"")} | X16: =CONCATENATE(D16,"_",E16,"_",U16,"+",W16,"_R1.fastq.gz") -> __+_R1.fastq.gz | Y16: =CONCATENATE(D16,"_",E16,"_",U16,"+",W16,"_R2.fastq.gz") -> __+_R2.fastq.gz
A17: 15 | G17: =100*F17 -> 0 | H17: =IF(G17<=100,100,100/F17) -> 100 | I17: =100-H17 -> 0 | K17: =H17*F17 -> 0 | L17: B03 | N17: B03 | Q17: =IF(ISBLANK(CONTROLE!$B$3),"","CMMZ_P"&CONTROLE!$B$3&"_0"&A17) -> CMMZ_P18_015 | R17: =IF(ISBLANK(CONTROLE!$B$3),"","P"&CONTROLE!$B$3&"_0"&A17) -> P18_015 | S17: ="CMMZ_P"&CONTROLE!$B$3&"_"&TEXT(A18,"00")&"_"&TEXT(B17,"ddMMMyy") -> CMMZ_P18_16_30Dec99 | T17: {=IFERROR(VLOOKUP(M17,{Indices_iTru!B:C;Indices_NEBNext!C:D;Indices_QIAseq!B:C},1,FALSE),"")} | U17: {=IFERROR(VLOOKUP(M17,{Indices_iTru!B:C;Indices_NEBNext!C:D;Indices_QIAseq!B:C},2,FALSE),"")} | V17: {=IFERROR(VLOOKUP(O17,{Indices_iTru!B:C;Indices_NEBNext!E:F;Indices_QIAseq!D:E},1,FALSE),"")} | W17: {=IFERROR(VLOOKUP(O17,{Indices_iTru!B:C;Indices_NEBNext!E:F;Indices_QIAseq!D:E},2,FALSE),"")} | X17: =CONCATENATE(D17,"_",E17,"_",U17,"+",W17,"_R1.fastq.gz") -> __+_R1.fastq.gz | Y17: =CONCATENATE(D17,"_",E17,"_",U17,"+",W17,"_R2.fastq.gz") -> __+_R2.fastq.gz
... A98: 96 | G98: =100*F98 -> 0 | H98: =IF(G98<=100,100,100/F98) -> 100 | I98: =100-H98 -> 0 | K98: =H98*F98 -> 0 | L98: H12 | N98: H12 | Q98: =IF(ISBLANK(CONTROLE!$B$3),"","CMMZ_P"&CONTROLE!$B$3&"_0"&A98) -> CMMZ_P18_096 | R98: =IF(ISBLANK(CONTROLE!$B$3),"","P"&CONTROLE!$B$3&"_0"&A98) -> P18_096 | S98: ="CMMZ_P"&CONTROLE!$B$3&"_"&TEXT(A99,"00")&"_"&TEXT(B98,"ddMMMyy") -> CMMZ_P18_00_30Dec99 | T98: {=IFERROR(VLOOKUP(M98,{Indices_iTru!B:C;Indices_NEBNext!C:D;Indices_QIAseq!B:C},1,FALSE),"")} | U98: {=IFERROR(VLOOKUP(M98,{Indices_iTru!B:C;Indices_NEBNext!C:D;Indices_QIAseq!B:C},2,FALSE),"")} | V98: {=IFERROR(VLOOKUP(O98,{Indices_iTru!B:C;Indices_NEBNext!E:F;Indices_QIAseq!D:E},1,FALSE),"")} | W98: {=IFERROR(VLOOKUP(O98,{Indices_iTru!B:C;Indices_NEBNext!E:F;Indices_QIAseq!D:E},2,FALSE),"")} | X98: =CONCATENATE(D98,"_",E98,"_",U98,"+",W98,"_R1.fastq.gz") -> __+_R1.fastq.gz | Y98: =CONCATENATE(D98,"_",E98,"_",U98,"+",W98,"_R2.fastq.gz") -> __+_R2.fastq.gz

Sheet 2.Organização para Pool de Enri
A1: POOL DE ENRIQUECIMENTO
A2: Organizar as amostras por valor da concentração da amostra no Pós-PCR (coluna F) do menor para o maior. CUIDADO PARA ORGANIZAR TODAS AS COLUNAS ADEQUADAMENTE, PARA QUE AS AMOSTRAS NAO SE MISTUREM. Utilizar amostras com concentrações parecidas na mesma pool.
A3: Contagem | B3: ID Biblioteca | C3: Espécie | D3: Código extração | E3: Pool | F3: Pós-PCR 13x (ng/uL)

Sheet 3.Pool de Enriquecimento
A1: POOL DE ENRIQUECIMENTO
A2: 1. Antes de começar, definir quantas amostras serão combinadas em cada pool. Recomendamos usar 10 a 12 amostras por pool, no máximo. Para amostras de concentração baixa, considere usar menos amostras por pool.
A3: 2. Após definir o número de pools, redefinir as células combinadas das colunas E, H, K, L, M e N.
A4: 3. Cada pool deve conter no mínimo 500 ng de DNA. Modificar formúla da coluna G para que cada amostra tenha quantidade igual de DNA e que a soma fique maior que 500 ng.
A5: Contagem | B5: ID Biblioteca | C5: Espécie | D5: Código extração | E5: Pool | F5: Pós-PCR 13x (ng/uL) | G5: uL necessários para que cada amostra tenha pelo menos 45ng de DNA | H5: Multiplicador necessário para aumentar o volume a ser pipetado | I5: uL a adicionar na pool de enriquecimento | J5: ID Biblioteca | K5: Volume Total (esperado) (soma dos volumes a adicionar na coluna I) | L5: [Pool] Qubit | M5: Volume a ressuspender após secar (sempre diminuir o volume para garantir a concentração mínima) | N5: [Pool Final] Qubit | O5: [Enriquecimento Pós-PCR] Qubit
A6: Placa 8 (lane 9) | B6: 26 | C6: Braunilla_sp_HYMZ0165 | D6: HYMZ0165 | E6: =CONCATENATE("CMMZ_P",CONTROLE!$B$3,"_A") -> CMMZ_P18_A | F6: 24.6 | G6: =50/F6 -> 2.0325203 | H6: 1.5 | I6: =$H$6*G6 -> 3.0487805 | J6: 26 | K6: =SUM(I6:I17) -> 53.317675
B7: 5 | C7: Pompilinae_sp_HYMZ0144 | D7: HYMZ0144 | F7: 15.5 | G7: =50/F7 -> 3.2258065 | I7: =$H$6*G7 -> 4.8387097 | J7: 5
B8: 12 | C8: Pompilocalus_sp_HYMZ0151 | D8: HYMZ0151 | F8: 27 | G8: =50/F8 -> 1.8518519 | I8: =$H$6*G8 -> 2.7777778 | J8: 12
B9: 39 | C9: Caenohalictus_incertus_HYMZ0587 | D9: HYMZ0587 | F9: 31.6 | G9: =50/F9 -> 1.5822785 | I9: =$H$6*G9 -> 2.3734177 | J9: 39
B10: 38 | C10: Caenohalictus_incertus_HYMZ0586 | D10: HYMZ0586 | F10: 19.6 | G10: =50/F10 -> 2.5510204 | I10: =$H$6*G10 -> 3.8265306 | J10: 38
A11: Placa 7 (lane 6) | B11: 27 | C11: Solenopsis_invicta_HYMZ0431 | D11: HYMZ0431 | F11: 18.2 | G11: =50/F11 -> 2.7472527 | I11: =$H$6*G11 -> 4.1208791 | J11: 27
B12: 55 | C12: Solenopsis_invicta_HYMZ0477 | D12: HYMZ0477 | F12: 21.8 | G12: =50/F12 -> 2.293578 | I12: =$H$6*G12 -> 3.440367 | J12: 55
B13: 59 | C13: Solenopsis_invicta_HYMZ0482 | D13: HYMZ0482 | F13: 5.82 | G13: =50/F13 -> 8.5910653 | I13: =$H$6*G13 -> 12.886598 | J13: 59
B14: 72 | C14: Solenopsis_invicta_HYMZ0498 | D14: HYMZ0498 | F14: 6.68 | G14: =50/F14 -> 7.4850299 | I14: =$H$6*G14 -> 11.227545 | J14: 72
B15: 92 | C15: Solenopsis_invicta_HYMZ0519 | D15: HYMZ0519 | F15: 15.7 | G15: =50/F15 -> 3.1847134 | I15: =$H$6*G15 -> 4.7770701 | J15: 92
A16: 11 | F16: 0 | G16: 0 | I16: =$H$6*G16 -> 0
A17: 12 | F17: 0 | G17: 0 | I17: =$H$6*G17 -> 0
A18: Placa 9 (lane 7) | B18: 76 | C18: Atta_sexdens_HYMZ0560 | D18: HYMZ0560 | E18: =CONCATENATE("CMMZ_P",CONTROLE!$B$3,"_B") -> CMMZ_P18_B | F18: 7.22 | G18: =50/F18 -> 6.9252078 | H18: 1.5 | I18: =$H$18*G18 -> 10.387812 | J18: 76 | K18: =SUM(I18:I29) -> 131.94653
B19: 77 | C19: Atta_sexdens_HYMZ0561 | D19: HYMZ0561 | F19: 15.5 | G19: =50/F19 -> 3.2258065 | I19: =$H$18*G19 -> 4.8387097 | J19: 77
B20: 78 | C20: Atta_sexdens_HYMZ0562 | D20: HYMZ0562 | F20: 27.6 | G20: =50/F20 -> 1.8115942 | I20: =$H$18*G20 -> 2.7173913 | J20: 78
B21: 79 | C21: Atta_sexdens_HYMZ0563 | D21: HYMZ0563 | F21: 9.6 | G21: =50/F21 -> 5.2083333 | I21: =$H$18*G21 -> 7.8125 | J21: 79
B22: 80 | C22: Atta_sexdens_HYMZ0564 | D22: HYMZ0564 | F22: 25 | G22: =50/F22 -> 2 | I22: =$H$18*G22 -> 3 | J22: 80
A23: Placa 10 (lane 8) | B23: 4 | C23: Ectatomma_permagnum_HYMZ0176 | D23: HYMZ0176 | F23: 6.26 | G23: =50/F23 -> 7.9872204 | I23: =$H$18*G23 -> 11.980831 | J23: 4
B24: 14 | C24: Ectatomma_permagnum_HYMZ0186 | D24: HYMZ0186 | F24: 2.64 | G24: =50/F24 -> 18.939394 | I24: =$H$18*G24 -> 28.409091 | J24: 14
B25: 16 | C25: Ectatomma_permagnum_HYMZ0188 | D25: HYMZ0188 | F25: 4.16 | G25: =50/F25 -> 12.019231 | I25: =$H$18*G25 -> 18.028846 | J25: 16
B26: 22 | C26: Ectatomma_cf.lugens_HYMZ0239 | D26: HYMZ0239 | F26: 3.54 | G26: =50/F26 -> 14.124294 | I26: =$H$18*G26 -> 21.186441 | J26: 22
B27: 23 | C27: Ectatomma_permagnum_HYMZ0195 | D27: HYMZ0195 | F27: 3.18 | G27: =50/F27 -> 15.72327 | I27: =$H$18*G27 -> 23.584906 | J27: 23
A28: 23 | G28: 0 | I28: =$H$18*G28 -> 0
A29: 24 | G29: 0 | I29: =$H$18*G29 -> 0
A30: 25 | E30: =CONCATENATE("CMMZ_P",CONTROLE!$B$3,"_C") -> CMMZ_P18_C | G30: =45/F30 -> #DIV/0! | I30: =$H$30*G30 -> #DIV/0! | K30: =SUM(I30:I41) -> #DIV/0!
A31: 26 | G31: =45/F31 -> #DIV/0! | I31: =$H$30*G31 -> #DIV/0!
A32: 27 | G32: =45/F32 -> #DIV/0! | I32: =$H$30*G32 -> #DIV/0!
A33: 28 | G33: =45/F33 -> #DIV/0! | I33: =$H$30*G33 -> #DIV/0!
A34: 29 | G34: =45/F34 -> #DIV/0! | I34: =$H$30*G34 -> #DIV/0!
A35: 30 | G35: =45/F35 -> #DIV/0! | I35: =$H$30*G35 -> #DIV/0!
A36: 31 | G36: =45/F36 -> #DIV/0! | I36: =$H$30*G36 -> #DIV/0!
A37: 32 | G37: =45/F37 -> #DIV/0! | I37: =$H$30*G37 -> #DIV/0!
A38: 33 | G38: =45/F38 -> #DIV/0! | I38: =$H$30*G38 -> #DIV/0!
A39: 34 | G39: =45/F39 -> #DIV/0! | I39: =$H$30*G39 -> #DIV/0!
A40: 35 | G40: =45/F40 -> #DIV/0! | I40: =$H$30*G40 -> #DIV/0!
...

Sheet 4.qPCR - montagem
B2: 1 | C2: 2 | D2: 3 | E2: 4 | F2: 5 | G2: 6 | H2: 7 | I2: 8 | J2: 9 | K2: 10 | L2: 11 | M2: 12
A3: A | B3: S1 | C3: S1 | D3: S1 | E3: S2 | F3: S2 | G3: S2 | H3: S3 | I3: S3 | J3: S3 | K3: S4 | L3: S4 | M3: S4
A4: B | B4: S5 | C4: S5 | D4: S5 | E4: S6 | F4: S6 | G4: S6
A5: C | B5: V1 1:2 | C5: V1 1:2 | D5: V1 1:2 | E5: V1 1:10 | F5: V1 1:10 | G5: V1 1:10 | H5: V2 1:2 | I5: V2 1:2 | J5: V2 1:2 | K5: V2 1:10 | L5: V2 1:10 | M5: V2 1:10
A6: D | B6: V3 1:2 | C6: V3 1:2 | D6: V3 1:2 | E6: V3 1:10 | F6: V3 1:10 | G6: V3 1:10 | H6: V4 1:2 | I6: V4 1:2 | J6: V4 1:2 | K6: V4 1:10 | L6: V4 1:10 | M6: V4 1:10
A7: E | B7: V5 1:2 | C7: V5 1:2 | D7: V5 1:2 | E7: V5 1:10 | F7: V5 1:10 | G7: V5 1:10 | H7: V6 1:2 | I7: V6 1:2 | J7: V6 1:2 | K7: V6 1:10 | L7: V6 1:10 | M7: V6 1:10
A8: F | B8: V7 1:2 | C8: V7 1:2 | D8: V7 1:2 | E8: V7 1:10 | F8: V7 1:10 | G8: V7 1:10 | H8: V8 1:2 | I8: V8 1:2 | J8: V8 1:2 | K8: V8 1:10 | L8: V8 1:10 | M8: V8 1:10
A9: G | B9: V9 1:2 | C9: V9 1:2 | D9: V9 1:2 | E9: V9 1:10 | F9: V9 1:10 | G9: V9 1:10 | H9: V10 1:2 | I9: V10 1:2 | J9: V10 1:2 | K9: V10 1:10 | L9: V10 1:10 | M9: V10 1:10
A10: H
A13: Kapa Lib. Quant. qPCR Protocol
A14: Step | C14: Temp | D14: Time | E14: Cycles | G14: Standards | H14: [dsDNA] (pM) | J14: For 10 uL rxn vol
A15: Activation/Denaturation | C15: 95C | D15: 5 min | E15: 1 cycle | G15: Std 1 | H15: 20 | J15: Reagent | K15: 1 Rxn (uL) | L15: 180 Rxn (uL) | M15: 30 Rxn (uL)
A16: Denaturation | C16: 95C | D16: 30 sec | E16: 35 cycles | G16: Std 2 | H16: 2 | J16: qPCR MM | K16: 6 | L16: 1188 | M16: 198
A17: Anneal/Elong/Data | C17: 60C | D17: 90 sec | G17: Std 3 | H17: 0.2 | J17: H2O | K17: 0 | L17: 0 | M17: 0
G18: Std 4 | H18: 0.02 | J18: Rox Low | K18: 0 | L18: 0 | M18: 0
G19: Std 5 | H19: 0.002 | J19: DNA | K19: 4
A20: Steps | G20: Std 6 | H20: 0.0002 | K20: 10 | L20: 1188 | M20: 198
A21: (1) Make dilution buffer (10 mM Tris-HCL, 0.05% Tween 20).
A22: (2) Make 1:1,000 and/or 1:1,000,000 dilutions. | J22: 1:2 = 1: 200,000
A23: (3) Prepare Master Mix and fill plate.
A24: (4) Add standards and diluted DNA as above. | J24: 1:10 = 1: 1,000,000
A25: (5) Run qPCR protocol.
A26: (6) Analyze data and calculate adjusted concentrartions in pM.

Sheet 5.qPCR - resultados
A1: Well | B1: Fluor | C1: Target | D1: Content | E1: Sample | F1: Biological Set Name | G1: Cq | H1: Cq Mean | I1: Cq Std. Dev | J1: Starting Quantity (SQ) | K1: Log Starting Quantity | L1: SQ Mean | M1: SQ Std. Dev | N1: Set Point
A2: A01 | B2: SYBR | D2: Std | G2: 9.7395916 | H2: 9.7395916 | I2: 0 | J2: 20 | K2: 1.30103 | L2: 20 | M2: 0 | N2: 60
A3: A02 | B3: SYBR | D3: Std | G3: 9.61005 | H3: 9.61005 | I3: 0 | J3: 20 | K3: 1.30103 | L3: 20 | M3: 0 | N3: 60 | P3: Sample Name | Q3: Dilution | R3: Conc1 (pM) | S3: Conc2 | T3: Conc3 | U3: Avg Conc (pM) | V3: Size Adjusted | W3: [Stock] (pM) | X3: [Stock] (nM) | Y3: AVG
A4: A03 | B4: SYBR | D4: Std | G4: 9.6616571 | H4: 9.6616571 | I4: 0 | J4: 20 | K4: 1.30103 | L4: 20 | M4: 0 | N4: 60 | P4: V1_1:200K | Q4: 200000 | R4: 0.90738633 | S4: 0.91753592 | T4: 0.94343865 | U4: =AVERAGE(R4:T4) -> 0.92278697 | V4: =U4*(452/600) -> 0.69516618 | W4: =V4*Q4 -> 139033.24 | X4: =W4/1000 -> 139.03324 | Y4: =AVERAGE(X4:X7) -> 150.49239 | AA4: Pool Name | AB4: # samples | AC4: [Stock] nM | AD4: Dilution | AE4: M/n | AF4: Dilution Factor | AG4: Sample Vol (uL) | AH4: total Input (M)
A5: A04 | B5: SYBR | D5: Std | G5: 14.515182 | H5: 14.515182 | I5: 0 | J5: 2 | K5: 0.30103 | L5: 2 | M5: 0 | N5: 60 | AA5: V1 | AB5: 10 | AC5: =Y4 -> 150.49239 | AD5: none | AE5: 10 | AF5: =AE5/AC5 -> 0.066448542 | AG5: =AF5*100 -> 6.6448542 | AH5: =AG5*AC5 -> 1000
A6: A05 | B6: SYBR | D6: Std | G6: 15.097814 | H6: 15.097814 | I6: 0 | J6: 2 | K6: 0.30103 | L6: 2 | M6: 0 | N6: 60 | P6: V1_1:1M | Q6: 1000000 | R6: 0.20830321 | S6: 0.22188888 | T6: 0.2147477 | U6: =AVERAGE(R6:T6) -> 0.21497993 | V6: =U6*(452/600) -> 0.16195155 | W6: =V6*Q6 -> 161951.55 | X6: =W6/1000 -> 161.95155 | AA6: V2 | AB6: 10 | AC6: =Y8 -> 155.52558 | AD6: none | AE6: 10 | AF6: =AE6/AC6 -> 0.064298106 | AG6: =AF6*100 -> 6.4298106 | AH6: =AG6*AC6 -> 1000
A7: A06 | B7: SYBR | D7: Std | G7: 15.818389 | H7: 15.818389 | I7: 0 | J7: 2 | K7: 0.30103 | L7: 2 | M7: 0 | N7: 60 | AA7: V3 | AB7: 10 | AC7: =Y12 -> 623.82847 | AD7: none | AE7: 10 | AF7: =AE7/AC7 -> 0.016030048 | AG7: =AF7*100 -> 1.6030048 | AH7: =AG7*AC7 -> 1000
A8: A07 | B8: SYBR | D8: Std | G8: 17.217608 | H8: 17.217608 | I8: 0 | J8: 0.2 | K8: -0.69897 | L8: 0.2 | M8: 0 | N8: 60 | P8: V2_1:200K | Q8: 200000 | R8: 1.9696253 | S8: 2.006374 | T8: 1.9457697 | U8: =AVERAGE(R8:T8) -> 1.973923 | V8: =U8*(452/600) -> 1.487022 | W8: =V8*Q8 -> 297404.4 | X8: =W8/1000 -> 297.4044 | Y8: =AVERAGE(X10:X11) -> 155.52558 | AA8: V4 | AB8: 10 | AC8: =Y16 -> 640.96965 | AD8: none | AE8: 10 | AF8: =AE8/AC8 -> 0.015601363 | AG8: =AF8*100 -> 1.5601363 | AH8: =AG8*AC8 -> 1000
A9: A08 | B9: SYBR | D9: Std | G9: 17.901787 | H9: 17.901787 | I9: 0 | J9: 0.2 | K9: -0.69897 | L9: 0.2 | M9: 0 | N9: 60 | AA9: V5 | AB9: 10 | AC9: =Y20 -> 607.44424 | AD9: none | AE9: 10 | AF9: =AE9/AC9 -> 0.016462416 | AG9: =AF9*100 -> 1.6462416 | AH9: =AG9*AC9 -> 1000
A10: A09 | B10: SYBR | D10: Std | G10: 18.149063 | H10: 18.149063 | I10: 0 | J10: 0.2 | K10: -0.69897 | L10: 0.2 | M10: 0 | N10: 60 | P10: V2_1:1M | Q10: 1000000 | R10: 0.20362738 | S10: 0.21676936 | T10: 0.19895291 | U10: =AVERAGE(R10:T10) -> 0.20644988 | V10: =U10*(452/600) -> 0.15552558 | W10: =V10*Q10 -> 155525.58 | X10: =W10/1000 -> 155.52558 | AA10: V6 | AB10: 10 | AC10: =Y24 -> 580.62104 | AD10: none | AE10: 10 | AF10: =AE10/AC10 -> 0.017222938 | AG10: =AF10*100 -> 1.7222938 | AH10: =AG10*AC10 -> 1000
A11: A10 | B11: SYBR | D11: Std | G11: 20.5456 | H11: 20.5456 | I11: 0 | J11: 0.02 | K11: -1.69897 | L11: 0.02 | M11: 0 | N11: 60 | AA11: V7 | AB11: 9 | AC11: =Y28 -> 333.37289 | AD11: none | AE11: 10 | AF11: =AE11/AC11 -> 0.029996441 | AG11: =AF11*100 -> 2.9996441 | AH11: =AG11*AC11 -> 1000
A12: A11 | B12: SYBR | D12: Std | G12: 19.681086 | H12: 19.681086 | I12: 0 | J12: 0.02 | K12: -1.69897 | L12: 0.02 | M12: 0 | N12: 60 | P12: V3_1:200K | Q12: 200000 | R12: 4.1485021 | S12: 3.815196 | T12: 4.4576651 | U12: =AVERAGE(R12:T12) -> 4.1404544 | V12: =U12*(452/600) -> 3.1191423 | W12: =V12*Q12 -> 623828.47 | X12: =W12/1000 -> 623.82847 | Y12: =AVERAGE(X12,X14:X15) -> 623.82847 | AA12: V8 | AB12: 9 | AC12: =Y32 -> 965.72154 | AD12: none | AE12: 10 | AF12: =AE12/AC12 -> 0.010354952 | AG12: =AF12*100 -> 1.0354952 | AH12: =AG12*AC12 -> 1000
A13: A12 | B13: SYBR | D13: Std | G13: 21.1924 | H13: 21.1924 | I13: 0 | J13: 0.02 | K13: -1.69897 | L13: 0.02 | M13: 0 | N13: 60 | AA13: V9 | AB13: 9 | AC13: =Y36 -> 816.83452 | AD13: none | AE13: 10 | AF13: =AE13/AC13 -> 0.012242382 | AG13: =AF13*100 -> 1.2242382 | AH13: =AG13*AC13 -> 1000
A14: B01 | B14: SYBR | D14: Std | G14: 24.627749 | H14: 24.627749 | I14: 0 | J14: 0.002 | K14: -2.69897 | L14: 0.002 | M14: 0 | N14: 60 | P14: V3_1:1M | Q14: 1000000 | U14: =AVERAGE(R14:T14) -> #DIV/0! | V14: =U14*(452/600) -> #DIV/0! | W14: =V14*Q14 -> #DIV/0! | AA14: V10 | AB14: 9 | AC14: =Y40 -> 954.66779 | AD14: none | AE14: 10 | AF14: =AE14/AC14 -> 0.010474848 | AG14: =AF14*100 -> 1.0474848 | AH14: =AG14*AC14 -> 1000
A15: B02 | B15: SYBR | D15: Std | G15: 25.143004 | H15: 25.143004 | I15: 0 | J15: 0.002 | K15: -2.69897 | L15: 0.002 | M15: 0 | N15: 60 | AA15: Total # | AB15: =SUM(AB5:AB14) -> 96 | AD15: Target [DNA] (C(f)) | AE15: =SUM(AE5:AE14) -> 100 | AF15: Vol DNA | AG15: =SUM(AG5:AG14) -> 25.913203
A16: B03 | B16: SYBR | D16: Std | G16: 24.910352 | H16: 24.910352 | I16: 0 | J16: 0.002 | K16: -2.69897 | L16: 0.002 | M16: 0 | N16: 60 | P16: V4_1:200K | Q16: 200000 | U16: =AVERAGE(R16:T16) -> #DIV/0! | V16: =U16*(452/600) -> #DIV/0! | W16: =V16*Q16 -> #DIV/0! | Y16: =AVERAGE(X16:X18) -> 640.96965 | AF16: Vol H2O | AG16: =100-AG15 -> 74.086797
A17: B04 | B17: SYBR | D17: Std | G17: 28.22132 | H17: 28.22132 | I17: 0 | J17: 0.0002 | K17: -3.69897 | L17: 0.0002 | M17: 0 | N17: 60 | AF17: V(f) | AG17: =SUM(AG15:AG16) -> 100
A18: B05 | B18: SYBR | D18: Std | G18: 28.463276 | H18: 28.463276 | I18: 0 | J18: 0.0002 | K18: -3.69897 | L18: 0.0002 | M18: 0 | N18: 60 | P18: V4_1:1M | Q18: 1000000 | R18: 0.74739867 | S18: 0.95332612 | T18: 0.85180922 | U18: =AVERAGE(R18:T18) -> 0.85084467 | V18: =U18*(452/600) -> 0.64096965 | W18: =V18*Q18 -> 640969.65 | X18: =W18/1000 -> 640.96965
A19: B06 | B19: SYBR | D19: Std | G19: 27.167323 | H19: 27.167323 | I19: 0 | J19: 0.0002 | K19: -3.69897 | L19: 0.0002 | M19: 0 | N19: 60 | AA19: Volume of Pool = | AB19: V(f) x C(f) x # samples in pool
A20: B07 | B20: SYBR | D20: Unkn | G20: NaN | H20: 0 | I20: 0 | J20: NaN | K20: NaN | L20: 0 | M20: 0 | N20: 60 | P20: V5_1:200K | Q20: 200000 | R20: 4.3796847 | S20: 4.2432614 | T20: 3.7116897 | U20: =AVERAGE(R20:T20) -> 4.1115453 | V20: =U20*(452/600) -> 3.0973641 | W20: =V20*Q20 -> 619472.82 | X20: =W20/1000 -> 619.47282 | Y20: =AVERAGE(X20:X23) -> 607.44424 | AB20: total # samples x C(i)
A21: B08 | B21: SYBR | D21: Unkn | G21: NaN | H21: 0 | I21: 0 | J21: NaN | K21: NaN | L21: 0 | M21: 0 | N21: 60
A22: B09 | B22: SYBR | D22: Unkn | G22: NaN | H22: 0 | I22: 0 | J22: NaN | K22: NaN | L22: 0 | M22: 0 | N22: 60 | P22: V5_1:1M | Q22: 1000000 | R22: 0.78613601 | S22: 0.79904099 | T22: 0.78594732 | U22: =AVERAGE(R22:T22) -> 0.79037477 | V22: =U22*(452/600) -> 0.59541566 | W22: =V22*Q22 -> 595415.66 | X22: =W22/1000 -> 595.41566 | AA22: V(f) = the desired volume of the final pool
A23: B10 | B23: SYBR | D23: Unkn | G23: NaN | H23: 0 | I23: 0 | J23: NaN | K23: NaN | L23: 0 | M23: 0 | N23: 60 | AA23: C(f) = the desired concentration of all the final pool
A24: B11 | B24: SYBR | D24: Unkn | G24: NaN | H24: 0 | I24: 0 | J24: NaN | K24: NaN | L24: 0 | M24: 0 | N24: 60 | P24: V6_1:200K | Q24: 200000 | R24: 4.6624922 | S24: 4.5649002 | T24: 5.1720851 | U24: =AVERAGE(R24:T24) -> 4.7998259 | V24: =U24*(452/600) -> 3.6158688 | W24: =V24*Q24 -> 723173.76 | X24: =W24/1000 -> 723.17376 | Y24: =AVERAGE(X24:X26) -> 580.62104 | AA24: C(i) = the initial concentration of the individual pool
A25: B12 | B25: SYBR | D25: Unkn | G25: NaN | H25: 0 | I25: 0 | J25: NaN | K25: NaN | L25: 0 | M25: 0 | N25: 60 | AA25: # samples in pool = number of samples of individual pool
A26: C01 | B26: SYBR | C26: target | D26: Unkn | E26: V1_1:200K | G26: 15.237282 | H26: 15.237282 | I26: 0 | J26: 0.90738633 | K26: -0.042207766 | L26: 0.90738633 | M26: 0 | N26: 60 | P26: V6_1:1M | Q26: 1000000 | R26: 0.62391931 | S26: 0.58179084 | T26: 0.53880971 | U26: =AVERAGE(R26:T26) -> 0.58150662 | V26: =U26*(452/600) -> 0.43806832 | W26: =V26*Q26 -> 438068.32 | X26: =W26/1000 -> 438.06832 | AA26: total # samples = number of samples in final pool
A27: C02 | B27: SYBR | C27: target | D27: Unkn | E27: V1_1:200K | G27: 15.220254 | H27: 15.220254 | I27: 0 | J27: 0.91753592 | K27: -0.037376924 | L27: 0.91753592 | M27: 0 | N27: 60
A28: C03 | B28: SYBR | C28: target | D28: Unkn | E28: V1_1:200K | G28: 15.177637 | H28: 15.177637 | I28: 0 | J28: 0.94343865 | K28: -0.025286336 | L28: 0.94343865 | M28: 0 | N28: 60 | P28: V7_1:200K | Q28: 200000 | R28: 3.1091745 | S28: 2.8619677 | T28: 2.6285077 | U28: =AVERAGE(R28:T28) -> 2.86655 | V28: =U28*(452/600) -> 2.1594676 | W28: =V28*Q28 -> 431893.53 | X28: =W28/1000 -> 431.89353 | Y28: =AVERAGE(X28:X30) -> 333.37289
A29: C04 | B29: SYBR | C29: target | D29: Unkn | E29: V1_1:1M | G29: 17.489961 | H29: 17.489961 | I29: 0 | J29: 0.20830321 | K29: -0.68130403 | L29: 0.20830321 | M29: 0 | N29: 60
A30: C05 | B30: SYBR | C30: target | D30: Unkn | E30: V1_1:1M | G30: 17.393243 | H30: 17.393243 | I30: 0 | J30: 0.22188888 | K30: -0.65386447 | L30: 0.22188888 | M30: 0 | N30: 60 | P30: V7_1:1M | Q30: 1000000 | R30: 0.28317447 | S30: 0.32425626 | T30: 0.32782157 | U30: =AVERAGE(R30:T30) -> 0.31175077 | V30: =U30*(452/600) -> 0.23485225 | W30: =V30*Q30 -> 234852.25 | X30: =W30/1000 -> 234.85225
A31: C06 | B31: SYBR | C31: target | D31: Unkn | E31: V1_1:1M | G31: 17.44332 | H31: 17.44332 | I31: 0 | J31: 0.2147477 | K31: -0.66807148 | L31: 0.2147477 | M31: 0 | N31: 60
A32: C07 | B32: SYBR | C32: target | D32: Unkn | E32: V2_1:200K | G32: 14.050868 | H32: 14.050868 | I32: 0 | J32: 1.9696253 | K32: 0.29438361 | L32: 1.9696253 | M32: 0 | N32: 60 | P32: V8_1:200K | Q32: 200000 | R32: 6.0104158 | S32: 6.3706497 | T32: 6.2393686 | U32: =AVERAGE(R32:T32) -> 6.2068114 | V32: =U32*(452/600) -> 4.6757979 | W32: =V32*Q32 -> 935159.58 | X32: =W32/1000 -> 935.15958 | Y32: =AVERAGE(X32:X34) -> 965.72154
A33: C08 | B33: SYBR | C33: target | D33: Unkn | E33: V2_1:200K | G33: 14.02257 | H33: 14.02257 | I33: 0 | J33: 2.006374 | K33: 0.30241189 | L33: 2.006374 | M33: 0 | N33: 60
A34: C09 | B34: SYBR | C34: target | D34: Unkn | E34: V2_1:200K | G34: 14.069522 | H34: 14.069522 | I34: 0 | J34: 1.9457697 | K34: 0.28909143 | L34: 1.9457697 | M34: 0 | N34: 60 | P34: V8_1:1M | Q34: 1000000 | R34: 1.3393447 | S34: 1.3288046 | T34: 1.2993514 | U34: =AVERAGE(R34:T34) -> 1.3225002 | V34: =U34*(452/600) -> 0.9962835 | W34: =V34*Q34 -> 996283.5 | X34: =W34/1000 -> 996.2835
A35: C10 | B35: SYBR | C35: target | D35: Unkn | E35: V2_1:1M | G35: 17.524715 | H35: 17.524715 | I35: 0 | J35: 0.20362738 | K35: -0.69116383 | L35: 0.20362738 | M35: 0 | N35: 60
A36: C11 | B36: SYBR | C36: target | D36: Unkn | E36: V2_1:1M | G36: 17.428976 | H36: 17.428976 | I36: 0 | J36: 0.21676936 | K36: -0.66400211 | L36: 0.21676936 | M36: 0 | N36: 60 | P36: V9_1:200K | Q36: 200000 | R36: 5.8675562 | S36: 5.9769976 | T36: 5.5420861 | U36: =AVERAGE(R36:T36) -> 5.7955466 | V36: =U36*(452/600) -> 4.3659785 | W36: =V36*Q36 -> 873195.69 | X36: =W36/1000 -> 873.19569 | Y36: =AVERAGE(X36:X38) -> 816.83452
A37: C12 | B37: SYBR | C37: target | D37: Unkn | E37: V2_1:1M | G37: 17.560266 | H37: 17.560266 | I37: 0 | J37: 0.19895291 | K37: -0.70124971 | L37: 0.19895291 | M37: 0 | N37: 60
A38: D01 | B38: SYBR | C38: target | D38: Unkn | E38: V3_1:200K | G38: 12.910571 | H38: 12.910571 | I38: 0 | J38: 4.1485021 | K38: 0.61789132 | L38: 4.1485021 | M38: 0 | N38: 60 | P38: V9_1:1M | Q38: 1000000 | R38: 0.96982877 | S38: 1.0350861 | T38: 1.0235188 | U38: =AVERAGE(R38:T38) -> 1.0094779 | V38: =U38*(452/600) -> 0.76047335 | W38: =V38*Q38 -> 760473.35 | X38: =W38/1000 -> 760.47335
A39: D02 | B39: SYBR | C39: target | D39: Unkn | E39: V3_1:200K | G39: 13.038784 | H39: 13.038784 | I39: 0 | J39: 3.815196 | K39: 0.58151686 | L39: 3.815196 | M39: 0 | N39: 60
A40: D03 | B40: SYBR | C40: target | D40: Unkn | E40: V3_1:200K | G40: 12.800541 | H40: 12.800541 | I40: 0 | J40: 4.4576651 | K40: 0.64910744 | L40: 4.4576651 | M40: 0 | N40: 60 | P40: V10_1:200K | Q40: 200000 | R40: 6.6529312 | S40: 6.7194677 | T40: 6.7575823 | U40: =AVERAGE(R40:T40) -> 6.7099937 | V40: =U40*(452/600) -> 5.0548619 | W40: =V40*Q40 -> 1010972.4 | X40: =W40/1000 -> 1010.9724 | Y40: =AVERAGE(X40:X42) -> 954.66779
...

Sheet 6.Pool de Sequenciamento
A1: ID Biblioteca | B1: [Stock] nM | C1: Dilution | D1: M/n | E1: Dilution Factor | F1: Sample Vol (uL) | G1: Sample Vol Real (uL)
B2: 8.48 | C2: none | D2: 1 | E2: =D2/B2 -> 0.11792453 | F2: =E2*100 -> 11.792453 | G2: 11.79
B3: 6.67 | C3: none | D3: 1 | E3: =D3/B3 -> 0.14992504 | F3: =E3*100 -> 14.992504 | G3: 14.99
B4: 4.21 | C4: none | D4: 1 | E4: =D4/B4 -> 0.23752969 | F4: =E4*100 -> 23.752969 | G4: 20
B5: 50.61 | C5: none | D5: 1 | E5: =D5/B5 -> 0.019758941 | F5: =E5*100 -> 1.9758941 | G5: 1.98
B6: 12.05 | C6: none | D6: 1 | E6: =D6/B6 -> 0.082987552 | F6: =E6*100 -> 8.2987552 | G6: 8.3
B7: 114.55 | C7: none | D7: 2 | E7: =D7/B7 -> 0.017459625 | F7: =E7*100 -> 1.7459625 | G7: 1.75
B8: 54.67 | C8: none | D8: 1 | E8: =D8/B8 -> 0.018291568 | F8: =E8*100 -> 1.8291568 | G8: 1.83
B9: 42.42 | C9: none | D9: 1 | E9: =D9/B9 -> 0.023573786 | F9: =E9*100 -> 2.3573786 | G9: 2.36
B10: 9.36 | C10: none | D10: 1 | E10: =D10/B10 -> 0.10683761 | F10: =E10*100 -> 10.683761 | G10: 10.68
B11: 43.13 | C11: none | D11: 1 | E11: =D11/B11 -> 0.023185718 | F11: =E11*100 -> 2.3185718 | G11: 2.32
B12: 6.73 | C12: none | D12: 1 | E12: =D12/B12 -> 0.14858841 | F12: =E12*100 -> 14.858841 | G12: 14.86
B13: 8.08 | C13: none | D13: 1 | E13: =D13/B13 -> 0.12376238 | F13: =E13*100 -> 12.376238 | G13: 12.38
... B153: 46.59 | C153: none | D153: 1 | E153: =D153/B153 -> 0.021463833 | F153: =E153*100 -> 2.1463833 | G153: 2.15
C154: Target [DNA] (C(f)) | D154: 144 | E154: Vol DNA | G154: =sum(G2:G153) -> 1197.18
E155: Vol H2O
E156: V(f) | G156: 1197.18
A158: Volume of Pool =
A161: V(f) = the desired volume of the final pool
A162: C(f) = the desired concentration of all the final pool
A163: C(i) = the initial concentration of the individual pool
A164: # samples in pool = number of samples of individual pool
A165: total # samples = number of samples in final pool

Sheet Indices_iTru
A1: count | B1: Primer Name | C1: Primer Index Sequence | D1: MiSeq & HiSeq Index Sequence | E1: MiniSeq & NextSeq Index Sequence | F1: complement of column C | G1: reverse of column H
A2: 1 | B2: iTru5_01_A | C2: ACCGACAA | D2: ACCGACAA | E2: TTGTCGGT | F2: TGGCTGTT | G2: TTGTCGGT
A3: 2 | B3: iTru5_01_B | C3: AGTGGCAA | D3: AGTGGCAA | E3: TTGCCACT | F3: TCACCGTT | G3: TTGCCACT
A4: 3 | B4: iTru5_01_C | C4: CACAGACT | D4: CACAGACT | E4: AGTCTGTG | F4: GTGTCTGA | G4: AGTCTGTG
A5: 4 | B5: iTru5_01_D | C5: CGACACTT | D5: CGACACTT | E5: AAGTGTCG | F5: GCTGTGAA | G5: AAGTGTCG
A6: 5 | B6: iTru5_01_E | C6: GACTTGTG | D6: GACTTGTG | E6: CACAAGTC | F6: CTGAACAC | G6: CACAAGTC
A7: 6 | B7: iTru5_01_F | C7: GTGAGACT | D7: GTGAGACT | E7: AGTCTCAC | F7: CACTCTGA | G7: AGTCTCAC
A8: 7 | B8: iTru5_01_G | C8: GTTCCATG | D8: GTTCCATG | E8: CATGGAAC | F8: CAAGGTAC | G8: CATGGAAC
A9: 8 | B9: iTru5_01_H | C9: TAGCTGAG | D9: TAGCTGAG | E9: CTCAGCTA | F9: ATCGACTC | G9: CTCAGCTA
A11: 9 | B11: iTru5_02_A | C11: CTTCGCAA | D11: CTTCGCAA | E11: TTGCGAAG | F11: GAAGCGTT | G11: TTGCGAAG
A12: 10 | B12: iTru5_02_B | C12: GTGGTATG | D12: GTGGTATG | E12: CATACCAC | F12: CACCATAC | G12: CATACCAC
A13: 11 | B13: iTru5_02_C | C13: CACTGTAG | D13: CACTGTAG | E13: CTACAGTG | F13: GTGACATC | G13: CTACAGTG
A14: 12 | B14: iTru5_02_D | C14: AGACGCTA | D14: AGACGCTA | E14: TAGCGTCT | F14: TCTGCGAT | G14: TAGCGTCT
... A432: 384 | B432: iTru5_124_H | C432: AACGCCTT | D432: AACGCCTT | E432: AAGGCGTT | F432: TTGCGGAA | G432: AAGGCGTT
A433: 1 | B433: iTru7_101_01 | C433: ACGTTACC
A434: 2 | B434: iTru7_101_02 | C434: CTGTGTTG
A435: 3 | B435: iTru7_101_03 | C435: TGAGGTGT
A436: 4 | B436: iTru7_101_04 | C436: GATCCATG
A437: 5 | B437: iTru7_101_05 | C437: GCCTATCA
A438: 6 | B438: iTru7_101_06 | C438: AACAACCG
A439: 7 | B439: iTru7_101_07 | C439: ACTCGTTG
A440: 8 | B440: iTru7_101_08 | C440: CCTATGGT
A441: 9 | B441: iTru7_101_09 | C441: TGTACACC
A442: 10 | B442: iTru7_101_10 | C442: GTATGCTG
A443: 11 | B443: iTru7_101_11 | C443: TGATGTCC
A444: 12 | B444: iTru7_101_12 | C444: GTCCTTCT
... A613: 168 | B613: iTru7_114_12 | C613: CTCAGAGT
A616: The sets below (sets 201-210) are tags that are NOT compatible with Illumina Indexes and were NOT included in the original synthesis (sets 01-13).
A618: 169 | B618: iTru7_201_01 | C618: CTTGGATG
A619: 170 | B619: iTru7_201_02 | C619: CAGTTGGA
A620: 171 | B620: iTru7_201_03 | C620: GATAGGCT
A621: 172 | B621: iTru7_201_04 | C621: TTGACAGG
A622: 173 | B622: iTru7_201_05 | C622: AGAATGCC
A623: 174 | B623: iTru7_201_06 | C623: CTACATCC
A624: 175 | B624: iTru7_201_07 | C624: TCATGGTG
A625: 176 | B625: iTru7_201_08 | C625: TACACGCT
A626: 177 | B626: iTru7_201_09 | C626: TACGGTTG
A627: 178 | B627: iTru7_201_10 | C627: GGATACCA
A628: 179 | B628: iTru7_201_11 | C628: TCGACATC
A629: 180 | B629: iTru7_201_12 | C629: GTTGTAGC
...

Sheet Indices_NEBNext
A1: Sample_Plate | B1: Sample_Well | C1: I7_Index_ID | D1: index | E1: I5_Index_ID | F1: index2
A2: E6440 | B2: A1 | C2: S762 | D2: TTACCGAC | E2: S512 | F2: CGTATTCG
A3: E6440 | B3: B1 | C3: S713 | D3: TCGTCTGA | E3: S586 | F3: TCAAGGAC
A4: E6440 | B4: C1 | C4: S736 | D4: TTCCAGGT | E4: S543 | F4: AAGCACTG
A5: E6440 | B5: D1 | C5: S709 | D5: TACGGTCT | E5: S575 | F5: GCAATGGA
A6: E6440 | B6: E1 | C6: S732 | D6: AAGACCGT | E6: S550 | F6: CAATCGAC
A7: E6440 | B7: F1 | C7: S774 | D7: CAGGTTCA | E7: S506 | F7: GGCGTTAT
A8: E6440 | B8: G1 | C8: S747 | D8: TAGGAGCT | E8: S524 | F8: GTTAAGGC
A9: E6440 | B9: H1 | C9: S794 | D9: TACTCCAG | E9: S590 | F9: CCTATACC
A10: E6440 | B10: A2 | C10: S729 | D10: AGTGACCT | E10: S591 | F10: CTCCTAGA
A11: E6440 | B11: B2 | C11: S777 | D11: AGCCTATC | E11: S526 | F11: GTTACGCA
A12: E6440 | B12: C2 | C12: S772 | D12: TCATCTCC | E12: S567 | F12: CTAGCAAG
... A97: E6440 | B97: H12 | C97: S733 | D97: CCACAACA | E97: S561 | F97: TGTGGTAC
A98: Sample_Plate | B98: Sample_Well | C98: I7_Index_ID | D98: index | E98: I5_Index_ID | F98: index2 | G98: Sample_Project | H98: Description
A99: E6442 | B99: A1 | C99: P7126 | D99: CACTGTAG | E99: P5134 | F99: AGTCGCTT
A100: E6442 | B100: B1 | C100: P7148 | D100: GTGCACGA | E100: P5136 | F100: GCCTATCA
A101: E6442 | B101: C1 | C101: P7133 | D101: ATGTTCCT | E101: P5107 | F101: GGCGCTGA
A102: E6442 | B102: D1 | C102: P7141 | D102: CATTATGG | E102: P5108 | F102: ATGTGACT
A103: E6442 | B103: E1 | C103: P7142 | D103: TCTTGTTT | E103: P5109 | F103: GTGAAAGG
A104: E6442 | B104: F1 | C104: P7143 | D104: GGCTTACT | E104: P5111 | F104: AGGGAAAG
A105: E6442 | B105: G1 | C105: P7146 | D105: ACGATATG | E105: P5117 | F105: GAATTGTC
A106: E6442 | B106: H1 | C106: P7152 | D106: ATCCGCAG | E106: P5119 | F106: AGTCGTGT
A107: E6442 | B107: A2 | C107: P7134 | D107: AAGCGACT | E107: P5135 | F107: GGATTCGT
A108: E6442 | B108: B2 | C108: P7136 | D108: TGATAGGC | E108: P5170 | F108: ACTCAGAC
A109: E6442 | B109: C2 | C109: P7153 | D109: AACACCAC | E109: P5122 | F109: CTCACACC
A110: E6442 | B110: D2 | C110: P7154 | D110: ACCTCTTC | E110: P5124 | F110: TATGCAAG
... A194: E6442 | B194: H12 | C194: P7997 | D194: TACCTGTG | E194: P5104 | F194: CTCGGTTG

Sheet Indices_QIAseq
A1: Sample_Well | B1: I7_Index_ID | C1: index | D1: I5_Index_ID | E1: index2
A2: PlateA_A01 | B2: i7QDIY-001 | C2: TGAACGTTGT | D2: i5QDIY-001 | E2: ATGGCCGACT
A3: PlateA_B01 | B3: i7QDIY-002 | C3: ACCAGACTTG | D3: i5QDIY-002 | E3: CGATGAGCAC
A4: PlateA_C01 | B4: i7QDIY-003 | C4: ACTGGCGAAC | D4: i5QDIY-003 | E4: GATAAGTCGA
A5: PlateA_D01 | B5: i7QDIY-004 | C5: GCGTTAGGCA | D5: i5QDIY-004 | E5: TCACGCCTTG
A6: PlateA_E01 | B6: i7QDIY-005 | C6: TTATCGGCCT | D6: i5QDIY-005 | E6: AGGAACACAA
A7: PlateA_F01 | B7: i7QDIY-006 | C7: GAGGTATAAG | D7: i5QDIY-006 | E7: CTCAGTAGGC
A8: PlateA_G01 | B8: i7QDIY-007 | C8: TCAAGGATTC | D8: i5QDIY-007 | E8: GAAGTGCCTG
A9: PlateA_H01 | B9: i7QDIY-008 | C9: CGAACCGAGA | D9: i5QDIY-008 | E9: TCTCTCGCCT
A10: PlateA_A02 | B10: i7QDIY-009 | C10: GAGCCAAGTT | D10: i5QDIY-009 | E10: AGGCACCTTC
A11: PlateA_B02 | B11: i7QDIY-010 | C11: AAGGCCGTAG | D11: i5QDIY-010 | E11: CTGTTGGTAA
A12: PlateA_C02 | B12: i7QDIY-011 | C12: TTAGAGAAGC | D12: i5QDIY-011 | E12: GCTGGTACCT
... A385: PlateD_H12 | B385: i7QDIY-384 | C385: CTCAGGCTGT | D385: i5QDIY-384 | E385: CCTAATTCGT
